<?xml version="1.0"?>
<robot name="g1_robot">
  
  <!-- World Link -->
  <link name="world"/>
  
  <!-- Base Link (Pelvis) -->
  <link name="base_link">
    <inertial>
      <origin xyz="0 0 -0.07605" rpy="0 0 0"/>
      <mass value="3.813"/>
      <inertia ixx="0.010549" ixy="0" ixz="0" iyy="0.0093089" iyz="0" izz="0.0079184"/>
    </inertial>
    <visual>
      <origin xyz="0 0 0" rpy="0 0 0"/>
      <geometry>
        <mesh filename="package://g1_description/assets/pelvis.STL"/>
      </geometry>
      <material name="silver">
        <color rgba="0.7 0.7 0.7 1"/>
      </material>
    </visual>
    <collision>
      <origin xyz="0 0 -0.08" rpy="0 0 0"/>
      <geometry>
        <sphere radius="0.07"/>
      </geometry>
    </collision>
  </link>
  
  <!-- World to Base Joint (Fixed for robot_state_publisher compatibility) -->
  <joint name="world_to_base" type="fixed">
    <parent link="world"/>
    <child link="base_link"/>
    <origin xyz="0 0 0.793" rpy="0 0 0"/>
  </joint>
  
  <!-- LEFT LEG -->
  <!-- Left Hip Pitch Link -->
  <link name="left_hip_pitch_link">
    <inertial>
      <origin xyz="0.002741 0.047791 -0.02606" rpy="0 0 0"/>
      <mass value="1.35"/>
      <inertia ixx="0.00181517" ixy="0" ixz="0" iyy="0.00153422" iyz="0" izz="0.00116212"/>
    </inertial>
    <visual>
      <origin xyz="0 0 0" rpy="0 0 0"/>
      <geometry>
        <mesh filename="package://g1_description/assets/left_hip_pitch_link.STL"/>
      </geometry>
      <material name="black">
        <color rgba="0.2 0.2 0.2 1"/>
      </material>
    </visual>
  </link>
  
  <joint name="left_hip_pitch_joint" type="revolute">
    <parent link="base_link"/>
    <child link="left_hip_pitch_link"/>
    <origin xyz="0 0.064452 -0.1027" rpy="0 0 0"/>
    <axis xyz="0 1 0"/>
    <limit lower="-2.5307" upper="2.8798" effort="88" velocity="10"/>
  </joint>
  
  <!-- Left Hip Roll Link -->
  <link name="left_hip_roll_link">
    <inertial>
      <origin xyz="0.029812 -0.001045 -0.087934" rpy="0 0 0"/>
      <mass value="1.52"/>
      <inertia ixx="0.00254986" ixy="0" ixz="0" iyy="0.00241169" iyz="0" izz="0.00148755"/>
    </inertial>
    <visual>
      <origin xyz="0 0 0" rpy="0 0 0"/>
      <geometry>
        <mesh filename="package://g1_description/assets/left_hip_roll_link.STL"/>
      </geometry>
      <material name="silver"/>
    </visual>
    <collision>
      <origin xyz="0.02 0 -0.04" rpy="0 0 0"/>
      <geometry>
        <cylinder radius="0.06" length="0.08"/>
      </geometry>
    </collision>
  </link>
  
  <joint name="left_hip_roll_joint" type="revolute">
    <parent link="left_hip_pitch_link"/>
    <child link="left_hip_roll_link"/>
    <origin xyz="0 0.052 -0.030465" rpy="0 -0.0873386 0"/>
    <axis xyz="1 0 0"/>
    <limit lower="-0.5236" upper="2.9671" effort="139" velocity="10"/>
  </joint>
  
  <!-- Left Hip Yaw Link -->
  <link name="left_hip_yaw_link">
    <inertial>
      <origin xyz="-0.057709 -0.010981 -0.15078" rpy="0 0 0"/>
      <mass value="1.702"/>
      <inertia ixx="0.00776166" ixy="0" ixz="0" iyy="0.00717575" iyz="0" izz="0.00160139"/>
    </inertial>
    <visual>
      <origin xyz="0 0 0" rpy="0 0 0"/>
      <geometry>
        <mesh filename="package://g1_description/assets/left_hip_yaw_link.STL"/>
      </geometry>
      <material name="silver"/>
    </visual>
    <collision>
      <origin xyz="-0.03 0 -0.1" rpy="0 0 0"/>
      <geometry>
        <cylinder radius="0.055" length="0.14"/>
      </geometry>
    </collision>
  </link>
  
  <joint name="left_hip_yaw_joint" type="revolute">
    <parent link="left_hip_roll_link"/>
    <child link="left_hip_yaw_link"/>
    <origin xyz="0.025001 0 -0.12412" rpy="0 0 0"/>
    <axis xyz="0 0 1"/>
    <limit lower="-2.7576" upper="2.7576" effort="88" velocity="10"/>
  </joint>
  
  <!-- Left Knee Link -->
  <link name="left_knee_link">
    <inertial>
      <origin xyz="0.005457 0.003964 -0.12074" rpy="0 0 0"/>
      <mass value="1.932"/>
      <inertia ixx="0.0113804" ixy="0" ixz="0" iyy="0.0112778" iyz="0" izz="0.00146458"/>
    </inertial>
    <visual>
      <origin xyz="0 0 0" rpy="0 0 0"/>
      <geometry>
        <mesh filename="package://g1_description/assets/left_knee_link.STL"/>
      </geometry>
      <material name="silver"/>
    </visual>
    <collision>
      <origin xyz="0.01 0 -0.075" rpy="0 0 0"/>
      <geometry>
        <cylinder radius="0.045" length="0.15"/>
      </geometry>
    </collision>
  </link>
  
  <joint name="left_knee_joint" type="revolute">
    <parent link="left_hip_yaw_link"/>
    <child link="left_knee_link"/>
    <origin xyz="-0.078273 0.0021489 -0.17734" rpy="0 0.0873386 0"/>
    <axis xyz="0 1 0"/>
    <limit lower="-0.087267" upper="2.8798" effort="139" velocity="10"/>
  </joint>
  
  <!-- Left Ankle Pitch Link -->
  <link name="left_ankle_pitch_link">
    <inertial>
      <origin xyz="-0.007269 0 0.011137" rpy="0 0 0"/>
      <mass value="0.074"/>
      <inertia ixx="1.89e-05" ixy="0" ixz="0" iyy="1.40805e-05" iyz="0" izz="6.9195e-06"/>
    </inertial>
    <visual>
      <origin xyz="0 0 0" rpy="0 0 0"/>
      <geometry>
        <mesh filename="package://g1_description/assets/left_ankle_pitch_link.STL"/>
      </geometry>
      <material name="silver"/>
    </visual>
  </link>
  
  <joint name="left_ankle_pitch_joint" type="revolute">
    <parent link="left_knee_link"/>
    <child link="left_ankle_pitch_link"/>
    <origin xyz="0 -9.4445e-05 -0.30001" rpy="0 0 0"/>
    <axis xyz="0 1 0"/>
    <limit lower="-0.87267" upper="0.5236" effort="50" velocity="10"/>
  </joint>
  
  <!-- Left Ankle Roll Link -->
  <link name="left_ankle_roll_link">
    <inertial>
      <origin xyz="0.026505 0 -0.016425" rpy="0 0 0"/>
      <mass value="0.608"/>
      <inertia ixx="0.00167218" ixy="0" ixz="0" iyy="0.0016161" iyz="0" izz="0.000217621"/>
    </inertial>
    <visual>
      <origin xyz="0 0 0" rpy="0 0 0"/>
      <geometry>
        <mesh filename="package://g1_description/assets/left_ankle_roll_link.STL"/>
      </geometry>
      <material name="black"/>
    </visual>
    <collision>
      <origin xyz="0.04 0 -0.029" rpy="0 0 0"/>
      <geometry>
        <box size="0.18 0.06 0.016"/>
      </geometry>
    </collision>
  </link>
  
  <joint name="left_ankle_roll_joint" type="revolute">
    <parent link="left_ankle_pitch_link"/>
    <child link="left_ankle_roll_link"/>
    <origin xyz="0 0 -0.017558" rpy="0 0 0"/>
    <axis xyz="1 0 0"/>
    <limit lower="-0.2618" upper="0.2618" effort="50" velocity="10"/>
  </joint>
  
  <!-- RIGHT LEG (mirrored structure) -->
  <!-- Right Hip Pitch Link -->
  <link name="right_hip_pitch_link">
    <inertial>
      <origin xyz="0.002741 -0.047791 -0.02606" rpy="0 0 0"/>
      <mass value="1.35"/>
      <inertia ixx="0.00181517" ixy="0" ixz="0" iyy="0.00153422" iyz="0" izz="0.00116212"/>
    </inertial>
    <visual>
      <origin xyz="0 0 0" rpy="0 0 0"/>
      <geometry>
        <mesh filename="package://g1_description/assets/right_hip_pitch_link.STL"/>
      </geometry>
      <material name="black"/>
    </visual>
  </link>
  
  <joint name="right_hip_pitch_joint" type="revolute">
    <parent link="base_link"/>
    <child link="right_hip_pitch_link"/>
    <origin xyz="0 -0.064452 -0.1027" rpy="0 0 0"/>
    <axis xyz="0 1 0"/>
    <limit lower="-2.5307" upper="2.8798" effort="88" velocity="10"/>
  </joint>
  
  <!-- Right Hip Roll Link -->
  <link name="right_hip_roll_link">
    <inertial>
      <origin xyz="0.029812 0.001045 -0.087934" rpy="0 0 0"/>
      <mass value="1.52"/>
      <inertia ixx="0.00254986" ixy="0" ixz="0" iyy="0.00241169" iyz="0" izz="0.00148755"/>
    </inertial>
    <visual>
      <origin xyz="0 0 0" rpy="0 0 0"/>
      <geometry>
        <mesh filename="package://g1_description/assets/right_hip_roll_link.STL"/>
      </geometry>
      <material name="silver"/>
    </visual>
    <collision>
      <origin xyz="0.02 0 -0.04" rpy="0 0 0"/>
      <geometry>
        <cylinder radius="0.06" length="0.08"/>
      </geometry>
    </collision>
  </link>
  
  <joint name="right_hip_roll_joint" type="revolute">
    <parent link="right_hip_pitch_link"/>
    <child link="right_hip_roll_link"/>
    <origin xyz="0 -0.052 -0.030465" rpy="0 -0.0873386 0"/>
    <axis xyz="1 0 0"/>
    <limit lower="-0.5236" upper="2.9671" effort="139" velocity="10"/>
  </joint>
  
  <!-- Right Hip Yaw Link -->
  <link name="right_hip_yaw_link">
    <inertial>
      <origin xyz="-0.057709 0.010981 -0.15078" rpy="0 0 0"/>
      <mass value="1.702"/>
      <inertia ixx="0.00776166" ixy="0" ixz="0" iyy="0.00717575" iyz="0" izz="0.00160139"/>
    </inertial>
    <visual>
      <origin xyz="0 0 0" rpy="0 0 0"/>
      <geometry>
        <mesh filename="package://g1_description/assets/right_hip_yaw_link.STL"/>
      </geometry>
      <material name="silver"/>
    </visual>
    <collision>
      <origin xyz="-0.03 0 -0.1" rpy="0 0 0"/>
      <geometry>
        <cylinder radius="0.055" length="0.14"/>
      </geometry>
    </collision>
  </link>
  
  <joint name="right_hip_yaw_joint" type="revolute">
    <parent link="right_hip_roll_link"/>
    <child link="right_hip_yaw_link"/>
    <origin xyz="0.025001 0 -0.12412" rpy="0 0 0"/>
    <axis xyz="0 0 1"/>
    <limit lower="-2.7576" upper="2.7576" effort="88" velocity="10"/>
  </joint>
  
  <!-- Right Knee Link -->
  <link name="right_knee_link">
    <inertial>
      <origin xyz="0.005457 -0.003964 -0.12074" rpy="0 0 0"/>
      <mass value="1.932"/>
      <inertia ixx="0.011374" ixy="0" ixz="0" iyy="0.0112843" iyz="0" izz="0.00146452"/>
    </inertial>
    <visual>
      <origin xyz="0 0 0" rpy="0 0 0"/>
      <geometry>
        <mesh filename="package://g1_description/assets/right_knee_link.STL"/>
      </geometry>
      <material name="silver"/>
    </visual>
    <collision>
      <origin xyz="0.01 0 -0.075" rpy="0 0 0"/>
      <geometry>
        <cylinder radius="0.045" length="0.15"/>
      </geometry>
    </collision>
  </link>
  
  <joint name="right_knee_joint" type="revolute">
    <parent link="right_hip_yaw_link"/>
    <child link="right_knee_link"/>
    <origin xyz="-0.078273 -0.0021489 -0.17734" rpy="0 0.0873386 0"/>
    <axis xyz="0 1 0"/>
    <limit lower="-0.087267" upper="2.8798" effort="139" velocity="10"/>
  </joint>
  
  <!-- Right Ankle Pitch Link -->
  <link name="right_ankle_pitch_link">
    <inertial>
      <origin xyz="-0.007269 0 0.011137" rpy="0 0 0"/>
      <mass value="0.074"/>
      <inertia ixx="1.89e-05" ixy="0" ixz="0" iyy="1.40805e-05" iyz="0" izz="6.9195e-06"/>
    </inertial>
    <visual>
      <origin xyz="0 0 0" rpy="0 0 0"/>
      <geometry>
        <mesh filename="package://g1_description/assets/right_ankle_pitch_link.STL"/>
      </geometry>
      <material name="silver"/>
    </visual>
  </link>
  
  <joint name="right_ankle_pitch_joint" type="revolute">
    <parent link="right_knee_link"/>
    <child link="right_ankle_pitch_link"/>
    <origin xyz="0 9.4445e-05 -0.30001" rpy="0 0 0"/>
    <axis xyz="0 1 0"/>
    <limit lower="-0.87267" upper="0.5236" effort="50" velocity="10"/>
  </joint>
  
  <!-- Right Ankle Roll Link -->
  <link name="right_ankle_roll_link">
    <inertial>
      <origin xyz="0.026505 0 -0.016425" rpy="0 0 0"/>
      <mass value="0.608"/>
      <inertia ixx="0.00167218" ixy="0" ixz="0" iyy="0.0016161" iyz="0" izz="0.000217621"/>
    </inertial>
    <visual>
      <origin xyz="0 0 0" rpy="0 0 0"/>
      <geometry>
        <mesh filename="package://g1_description/assets/right_ankle_roll_link.STL"/>
      </geometry>
      <material name="black"/>
    </visual>
    <collision>
      <origin xyz="0.04 0 -0.029" rpy="0 0 0"/>
      <geometry>
        <box size="0.18 0.06 0.016"/>
      </geometry>
    </collision>
  </link>
  
  <joint name="right_ankle_roll_joint" type="revolute">
    <parent link="right_ankle_pitch_link"/>
    <child link="right_ankle_roll_link"/>
    <origin xyz="0 0 -0.017558" rpy="0 0 0"/>
    <axis xyz="1 0 0"/>
    <limit lower="-0.2618" upper="0.2618" effort="50" velocity="10"/>
  </joint>
  
  <!-- WAIST -->
  <!-- Waist Yaw Link -->
  <link name="waist_yaw_link">
    <inertial>
      <origin xyz="0.003494 0.000233 0.018034" rpy="0 0 0"/>
      <mass value="0.214"/>
      <inertia ixx="0.000163531" ixy="0" ixz="0" iyy="0.000107714" iyz="0" izz="0.000102205"/>
    </inertial>
    <visual>
      <origin xyz="0 0 0" rpy="0 0 0"/>
      <geometry>
        <mesh filename="package://g1_description/assets/waist_yaw_link_rev_1_0.STL"/>
      </geometry>
      <material name="silver"/>
    </visual>
  </link>
  
  <joint name="waist_yaw_joint" type="revolute">
    <parent link="base_link"/>
    <child link="waist_yaw_link"/>
    <origin xyz="0 0 0" rpy="0 0 0"/>
    <axis xyz="0 0 1"/>
    <limit lower="-2.618" upper="2.618" effort="88" velocity="10"/>
  </joint>
  
  <!-- Waist Roll Link -->
  <link name="waist_roll_link">
    <inertial>
      <origin xyz="0 2.3e-05 0" rpy="0 0 0"/>
      <mass value="0.086"/>
      <inertia ixx="8.245e-06" ixy="0" ixz="0" iyy="7.079e-06" iyz="0" izz="6.339e-06"/>
    </inertial>
    <visual>
      <origin xyz="0 0 0" rpy="0 0 0"/>
      <geometry>
        <mesh filename="package://g1_description/assets/waist_roll_link_rev_1_0.STL"/>
      </geometry>
      <material name="silver"/>
    </visual>
  </link>
  
  <joint name="waist_roll_joint" type="revolute">
    <parent link="waist_yaw_link"/>
    <child link="waist_roll_link"/>
    <origin xyz="-0.0039635 0 0.044" rpy="0 0 0"/>
    <axis xyz="1 0 0"/>
    <limit lower="-0.52" upper="0.52" effort="50" velocity="10"/>
  </joint>
  
  <!-- Torso Link -->
  <link name="torso_link">
    <inertial>
      <origin xyz="0.00203158 0.000339683 0.184568" rpy="0 0 0"/>
      <mass value="7.818"/>
      <inertia ixx="0.121847" ixy="0" ixz="0" iyy="0.109825" iyz="0" izz="0.0273735"/>
    </inertial>
    <visual>
      <origin xyz="0 0 0" rpy="0 0 0"/>
      <geometry>
        <mesh filename="package://g1_description/assets/torso_link_rev_1_0.STL"/>
      </geometry>
      <material name="silver"/>
    </visual>
    <visual>
      <origin xyz="0.0039635 0 -0.044" rpy="0 0 0"/>
      <geometry>
        <mesh filename="package://g1_description/assets/logo_link.STL"/>
      </geometry>
      <material name="black"/>
    </visual>
    <visual>
      <origin xyz="0.0039635 0 -0.044" rpy="0 0 0"/>
      <geometry>
        <mesh filename="package://g1_description/assets/head_link.STL"/>
      </geometry>
      <material name="black"/>
    </visual>
    <collision>
      <origin xyz="0.01 0 0.14" rpy="0 0 0"/>
      <geometry>
        <cylinder radius="0.09" length="0.12"/>
      </geometry>
    </collision>
    <collision>
      <origin xyz="0 0 .43" rpy="0 0 0"/>
      <geometry>
        <sphere radius="0.06"/>
      </geometry>
    </collision>
  </link>
  
  <joint name="waist_pitch_joint" type="revolute">
    <parent link="waist_roll_link"/>
    <child link="torso_link"/>
    <origin xyz="0 0 0" rpy="0 0 0"/>
    <axis xyz="0 1 0"/>
    <limit lower="-0.52" upper="0.52" effort="50" velocity="10"/>
  </joint>
  
  <!-- LEFT ARM -->
  <!-- Left Shoulder Pitch Link -->
  <link name="left_shoulder_pitch_link">
    <inertial>
      <origin xyz="0 0.035892 -0.011628" rpy="0 0 0"/>
      <mass value="0.718"/>
      <inertia ixx="0.000465864" ixy="0" ixz="0" iyy="0.000432842" iyz="0" izz="0.000406394"/>
    </inertial>
    <visual>
      <origin xyz="0 0 0" rpy="0 0 0"/>
      <geometry>
        <mesh filename="package://g1_description/assets/left_shoulder_pitch_link.STL"/>
      </geometry>
      <material name="silver"/>
    </visual>
  </link>
  
  <joint name="left_shoulder_pitch_joint" type="revolute">
    <parent link="torso_link"/>
    <child link="left_shoulder_pitch_link"/>
    <origin xyz="0.0039563 0.10022 0.24778" rpy="0.139201 0 0"/>
    <axis xyz="0 1 0"/>
    <limit lower="-3.0892" upper="2.6704" effort="25" velocity="10"/>
  </joint>
  
  <!-- Left Shoulder Roll Link -->
  <link name="left_shoulder_roll_link">
    <inertial>
      <origin xyz="-0.000227 0.00727 -0.063243" rpy="0 0 0"/>
      <mass value="0.643"/>
      <inertia ixx="0.000691311" ixy="0" ixz="0" iyy="0.000618011" iyz="0" izz="0.000388977"/>
    </inertial>
    <visual>
      <origin xyz="0 0 0" rpy="0 0 0"/>
      <geometry>
        <mesh filename="package://g1_description/assets/left_shoulder_roll_link.STL"/>
      </geometry>
      <material name="silver"/>
    </visual>
  </link>
  
  <joint name="left_shoulder_roll_joint" type="revolute">
    <parent link="left_shoulder_pitch_link"/>
    <child link="left_shoulder_roll_link"/>
    <origin xyz="0 0.038 -0.013831" rpy="-0.139172 0 0"/>
    <axis xyz="1 0 0"/>
    <limit lower="-1.5882" upper="2.2515" effort="25" velocity="10"/>
  </joint>
  
  <!-- Left Shoulder Yaw Link -->
  <link name="left_shoulder_yaw_link">
    <inertial>
      <origin xyz="0.010773 -0.002949 -0.072009" rpy="0 0 0"/>
      <mass value="0.734"/>
      <inertia ixx="0.00106187" ixy="0" ixz="0" iyy="0.00103217" iyz="0" izz="0.000400661"/>
    </inertial>
    <visual>
      <origin xyz="0 0 0" rpy="0 0 0"/>
      <geometry>
        <mesh filename="package://g1_description/assets/left_shoulder_yaw_link.STL"/>
      </geometry>
      <material name="silver"/>
    </visual>
    <collision>
      <origin xyz="0 0 -0.015" rpy="0 0 0"/>
      <geometry>
        <cylinder radius="0.035" length="0.13"/>
      </geometry>
    </collision>
  </link>
  
  <joint name="left_shoulder_yaw_joint" type="revolute">
    <parent link="left_shoulder_roll_link"/>
    <child link="left_shoulder_yaw_link"/>
    <origin xyz="0 0.00624 -0.1032" rpy="0 0 0"/>
    <axis xyz="0 0 1"/>
    <limit lower="-2.618" upper="2.618" effort="25" velocity="10"/>
  </joint>
  
  <!-- Left Elbow Link -->
  <link name="left_elbow_link">
    <inertial>
      <origin xyz="0.064956 0.004454 -0.010062" rpy="0 0 0"/>
      <mass value="0.6"/>
      <inertia ixx="0.000443035" ixy="0" ixz="0" iyy="0.000421612" iyz="0" izz="0.000259353"/>
    </inertial>
    <visual>
      <origin xyz="0 0 0" rpy="0 0 0"/>
      <geometry>
        <mesh filename="package://g1_description/assets/left_elbow_link.STL"/>
      </geometry>
      <material name="silver"/>
    </visual>
    <collision>
      <origin xyz="0.035 0 -0.01" rpy="0 0 0"/>
      <geometry>
        <cylinder radius="0.035" length="0.09"/>
      </geometry>
    </collision>
  </link>
  
  <joint name="left_elbow_joint" type="revolute">
    <parent link="left_shoulder_yaw_link"/>
    <child link="left_elbow_link"/>
    <origin xyz="0.015783 0 -0.080518" rpy="0 0 0"/>
    <axis xyz="0 1 0"/>
    <limit lower="-1.0472" upper="2.0944" effort="25" velocity="10"/>
  </joint>
  
  <!-- Left Wrist Roll Link -->
  <link name="left_wrist_roll_link">
    <inertial>
      <origin xyz="0.0171394 0.000537591 4.8864e-07" rpy="0 0 0"/>
      <mass value="0.085445"/>
      <inertia ixx="5.48211e-05" ixy="0" ixz="0" iyy="4.96646e-05" iyz="0" izz="3.57798e-05"/>
    </inertial>
    <visual>
      <origin xyz="0 0 0" rpy="0 0 0"/>
      <geometry>
        <mesh filename="package://g1_description/assets/left_wrist_roll_link.STL"/>
      </geometry>
      <material name="silver"/>
    </visual>
  </link>
  
  <joint name="left_wrist_roll_joint" type="revolute">
    <parent link="left_elbow_link"/>
    <child link="left_wrist_roll_link"/>
    <origin xyz="0.1 0.00188791 -0.01" rpy="0 0 0"/>
    <axis xyz="1 0 0"/>
    <limit lower="-1.97222" upper="1.97222" effort="25" velocity="10"/>
  </joint>
  
  <!-- Left Wrist Pitch Link -->
  <link name="left_wrist_pitch_link">
    <inertial>
      <origin xyz="0.0229999 -0.00111685 -0.00111658" rpy="0 0 0"/>
      <mass value="0.48405"/>
      <inertia ixx="0.000430353" ixy="0" ixz="0" iyy="0.000429873" iyz="0" izz="0.000164648"/>
    </inertial>
    <visual>
      <origin xyz="0 0 0" rpy="0 0 0"/>
      <geometry>
        <mesh filename="package://g1_description/assets/left_wrist_pitch_link.STL"/>
      </geometry>
      <material name="silver"/>
    </visual>
    <collision>
      <origin xyz="0.025 0 0" rpy="0 0 0"/>
      <geometry>
        <cylinder radius="0.035" length="0.07"/>
      </geometry>
    </collision>
  </link>
  
  <joint name="left_wrist_pitch_joint" type="revolute">
    <parent link="left_wrist_roll_link"/>
    <child link="left_wrist_pitch_link"/>
    <origin xyz="0.038 0 0" rpy="0 0 0"/>
    <axis xyz="0 1 0"/>
    <limit lower="-1.61443" upper="1.61443" effort="5" velocity="10"/>
  </joint>
  
  <!-- Left Wrist Yaw Link -->
  <link name="left_wrist_yaw_link">
    <inertial>
      <origin xyz="0.0708244 0.000191745 0.00161742" rpy="0 0 0"/>
      <mass value="0.254576"/>
      <inertia ixx="0.000646113" ixy="0" ixz="0" iyy="0.000559993" iyz="0" izz="0.000147566"/>
    </inertial>
    <visual>
      <origin xyz="0 0 0" rpy="0 0 0"/>
      <geometry>
        <mesh filename="package://g1_description/assets/left_wrist_yaw_link.STL"/>
      </geometry>
      <material name="silver"/>
    </visual>
    <visual>
      <origin xyz="0.0415 0.003 0" rpy="0 0 0"/>
      <geometry>
        <mesh filename="package://g1_description/assets/left_rubber_hand.STL"/>
      </geometry>
      <material name="silver"/>
    </visual>
    <collision>
      <origin xyz="0.11 -0.01 0" rpy="0 0 0"/>
      <geometry>
        <cylinder radius="0.035" length="0.08"/>
      </geometry>
    </collision>
  </link>
  
  <joint name="left_wrist_yaw_joint" type="revolute">
    <parent link="left_wrist_pitch_link"/>
    <child link="left_wrist_yaw_link"/>
    <origin xyz="0.046 0 0" rpy="0 0 0"/>
    <axis xyz="0 0 1"/>
    <limit lower="-1.61443" upper="1.61443" effort="5" velocity="10"/>
  </joint>
  
  <!-- RIGHT ARM (mirrored structure) -->
  <!-- Right Shoulder Pitch Link -->
  <link name="right_shoulder_pitch_link">
    <inertial>
      <origin xyz="0 -0.035892 -0.011628" rpy="0 0 0"/>
      <mass value="0.718"/>
      <inertia ixx="0.000465864" ixy="0" ixz="0" iyy="0.000432842" iyz="0" izz="0.000406394"/>
    </inertial>
    <visual>
      <origin xyz="0 0 0" rpy="0 0 0"/>
      <geometry>
        <mesh filename="package://g1_description/assets/right_shoulder_pitch_link.STL"/>
      </geometry>
      <material name="silver"/>
    </visual>
  </link>
  
  <joint name="right_shoulder_pitch_joint" type="revolute">
    <parent link="torso_link"/>
    <child link="right_shoulder_pitch_link"/>
    <origin xyz="0.0039563 -0.10021 0.24778" rpy="-0.139201 0 0"/>
    <axis xyz="0 1 0"/>
    <limit lower="-3.0892" upper="2.6704" effort="25" velocity="10"/>
  </joint>
  
  <!-- Right Shoulder Roll Link -->
  <link name="right_shoulder_roll_link">
    <inertial>
      <origin xyz="-0.000227 -0.00727 -0.063243" rpy="0 0 0"/>
      <mass value="0.643"/>
      <inertia ixx="0.000691311" ixy="0" ixz="0" iyy="0.000618011" iyz="0" izz="0.000388977"/>
    </inertial>
    <visual>
      <origin xyz="0 0 0" rpy="0 0 0"/>
      <geometry>
        <mesh filename="package://g1_description/assets/right_shoulder_roll_link.STL"/>
      </geometry>
      <material name="silver"/>
    </visual>
  </link>
  
  <joint name="right_shoulder_roll_joint" type="revolute">
    <parent link="right_shoulder_pitch_link"/>
    <child link="right_shoulder_roll_link"/>
    <origin xyz="0 -0.038 -0.013831" rpy="0.139172 0 0"/>
    <axis xyz="1 0 0"/>
    <limit lower="-2.2515" upper="1.5882" effort="25" velocity="10"/>
  </joint>
  
  <!-- Right Shoulder Yaw Link -->
  <link name="right_shoulder_yaw_link">
    <inertial>
      <origin xyz="0.010773 0.002949 -0.072009" rpy="0 0 0"/>
      <mass value="0.734"/>
      <inertia ixx="0.00106187" ixy="0" ixz="0" iyy="0.00103217" iyz="0" izz="0.000400661"/>
    </inertial>
    <visual>
      <origin xyz="0 0 0" rpy="0 0 0"/>
      <geometry>
        <mesh filename="package://g1_description/assets/right_shoulder_yaw_link.STL"/>
      </geometry>
      <material name="silver"/>
    </visual>
    <collision>
      <origin xyz="0 0 -0.015" rpy="0 0 0"/>
      <geometry>
        <cylinder radius="0.035" length="0.13"/>
      </geometry>
    </collision>
  </link>
  
  <joint name="right_shoulder_yaw_joint" type="revolute">
    <parent link="right_shoulder_roll_link"/>
    <child link="right_shoulder_yaw_link"/>
    <origin xyz="0 -0.00624 -0.1032" rpy="0 0 0"/>
    <axis xyz="0 0 1"/>
    <limit lower="-2.618" upper="2.618" effort="25" velocity="10"/>
  </joint>
  
  <!-- Right Elbow Link -->
  <link name="right_elbow_link">
    <inertial>
      <origin xyz="0.064956 -0.004454 -0.010062" rpy="0 0 0"/>
      <mass value="0.6"/>
      <inertia ixx="0.000443035" ixy="0" ixz="0" iyy="0.000421612" iyz="0" izz="0.000259353"/>
    </inertial>
    <visual>
      <origin xyz="0 0 0" rpy="0 0 0"/>
      <geometry>
        <mesh filename="package://g1_description/assets/right_elbow_link.STL"/>
      </geometry>
      <material name="silver"/>
    </visual>
    <collision>
      <origin xyz="0.035 0 -0.01" rpy="0 0 0"/>
      <geometry>
        <cylinder radius="0.035" length="0.09"/>
      </geometry>
    </collision>
  </link>
  
  <joint name="right_elbow_joint" type="revolute">
    <parent link="right_shoulder_yaw_link"/>
    <child link="right_elbow_link"/>
    <origin xyz="0.015783 0 -0.080518" rpy="0 0 0"/>
    <axis xyz="0 1 0"/>
    <limit lower="-1.0472" upper="2.0944" effort="25" velocity="10"/>
  </joint>
  
  <!-- Right Wrist Roll Link -->
  <link name="right_wrist_roll_link">
    <inertial>
      <origin xyz="0.0171394 -0.000537591 4.8864e-07" rpy="0 0 0"/>
      <mass value="0.085445"/>
      <inertia ixx="5.48211e-05" ixy="0" ixz="0" iyy="4.96646e-05" iyz="0" izz="3.57798e-05"/>
    </inertial>
    <visual>
      <origin xyz="0 0 0" rpy="0 0 0"/>
      <geometry>
        <mesh filename="package://g1_description/assets/right_wrist_roll_link.STL"/>
      </geometry>
      <material name="silver"/>
    </visual>
  </link>
  
  <joint name="right_wrist_roll_joint" type="revolute">
    <parent link="right_elbow_link"/>
    <child link="right_wrist_roll_link"/>
    <origin xyz="0.1 -0.00188791 -0.01" rpy="0 0 0"/>
    <axis xyz="1 0 0"/>
    <limit lower="-1.97222" upper="1.97222" effort="25" velocity="10"/>
  </joint>
  
  <!-- Right Wrist Pitch Link -->
  <link name="right_wrist_pitch_link">
    <inertial>
      <origin xyz="0.0229999 0.00111685 -0.00111658" rpy="0 0 0"/>
      <mass value="0.48405"/>
      <inertia ixx="0.000430353" ixy="0" ixz="0" iyy="0.000429873" iyz="0" izz="0.000164648"/>
    </inertial>
    <visual>
      <origin xyz="0 0 0" rpy="0 0 0"/>
      <geometry>
        <mesh filename="package://g1_description/assets/right_wrist_pitch_link.STL"/>
      </geometry>
      <material name="silver"/>
    </visual>
    <collision>
      <origin xyz="0.025 0 0" rpy="0 0 0"/>
      <geometry>
        <cylinder radius="0.035" length="0.07"/>
      </geometry>
    </collision>
  </link>
  
  <joint name="right_wrist_pitch_joint" type="revolute">
    <parent link="right_wrist_roll_link"/>
    <child link="right_wrist_pitch_link"/>
    <origin xyz="0.038 0 0" rpy="0 0 0"/>
    <axis xyz="0 1 0"/>
    <limit lower="-1.61443" upper="1.61443" effort="5" velocity="10"/>
  </joint>
  
  <!-- Right Wrist Yaw Link -->
  <link name="right_wrist_yaw_link">
    <inertial>
      <origin xyz="0.0708244 -0.000191745 0.00161742" rpy="0 0 0"/>
      <mass value="0.254576"/>
      <inertia ixx="0.000646113" ixy="0" ixz="0" iyy="0.000559993" iyz="0" izz="0.000147566"/>
    </inertial>
    <visual>
      <origin xyz="0 0 0" rpy="0 0 0"/>
      <geometry>
        <mesh filename="package://g1_description/assets/right_wrist_yaw_link.STL"/>
      </geometry>
      <material name="silver"/>
    </visual>
    <visual>
      <origin xyz="0.0415 -0.003 0" rpy="0 0 0"/>
      <geometry>
        <mesh filename="package://g1_description/assets/right_rubber_hand.STL"/>
      </geometry>
      <material name="silver"/>
    </visual>
    <collision>
      <origin xyz="0.11 0.01 0" rpy="0 0 0"/>
      <geometry>
        <cylinder radius="0.035" length="0.08"/>
      </geometry>
    </collision>
  </link>
  
  <joint name="right_wrist_yaw_joint" type="revolute">
    <parent link="right_wrist_pitch_link"/>
    <child link="right_wrist_yaw_link"/>
    <origin xyz="0.046 0 0" rpy="0 0 0"/>
    <axis xyz="0 0 1"/>
    <limit lower="-1.61443" upper="1.61443" effort="5" velocity="10"/>
  </joint>

</robot>
